Workbook

Sheet Sheet1
B3: Calculating ROIC of Asian Paints Using Intrinsic Value
B5: Particular | C5: 42064 | D5: 42430 | E5: 42795 | F5: 43160 | G5: 43525 | H5: 43891 | I5: 44256 | J5: 44621 | K5: 44986 | L5: 45352 | M5: 45717 | N5: 46082
B7: Equity Capital | C7: 96 | D7: 96 | E7: 96 | F7: 96 | G7: 96 | H7: 96 | I7: 96 | J7: 96 | K7: 96 | L7: 96 | M7: 96 | N7: 96
B8: Reserves | C8: 4646 | D8: 6429 | E8: 7508 | F8: 8314 | G8: 9375 | H8: 10034 | I8: 12710 | J8: 13716 | K8: 15896 | L8: 18632 | M8: 19304 | N8: 21276
B9: Borrowings -
B10: Long term Borrowings | C10: 78 | D10: 73 | E10: 41 | F10: 28 | G10: 19 | H10: 19 | I10: 15 | J10: 45 | K10: 76 | L10: 54 | M10: 260 | N10: 1247
B11: Short term Borrowings | C11: 332 | D11: 231 | E11: 504 | F11: 492 | G11: 597 | H11: 321 | I11: 334 | J11: 731 | K11: 896 | L11: 1053 | M11: 604 | N11: 1046
B12: Lease Liabilities | C12: 0 | D12: 0 | E12: 0 | F12: 0 | G12: 693 | H12: 764 | I12: 745 | J12: 811 | K12: 960 | L12: 1367 | M12: 1427 | N12: 1636
B13: Other Borrowings | C13: 8 | D13: 20 | E13: 15 | F13: 13 | G13: 11 | H13: 15 | I13: 0 | J13: 0 | K13: 0 | L13: 0 | M13: 0
B14: Other Liabilities -
B15: Non controlling int | C15: 264 | D15: 384 | E15: 375 | F15: 328 | G15: 361 | H15: 404 | I15: 423 | J15: 388 | K15: 454 | L15: 695 | M15: 659 | N15: 643
B16: Trade Payables | C16: 1549 | D16: 1565 | E16: 1923 | F16: 2160 | G16: 2394 | H16: 2137 | I16: 3379 | J16: 4164 | K16: 3635 | L16: 3831 | M16: 3848 | N16: 3863
B17: Advance from Customers | C17: 5 | D17: 12 | E17: 17 | F17: 16 | G17: 13 | H17: 29 | I17: 41 | J17: 76 | K17: 108 | L17: 154 | M17: 173
B18: Other liability items | C18: 1937 | D18: 1750 | E18: 1925 | F18: 2316 | G18: 2690 | H18: 2320 | I18: 2613 | J18: 2932 | K18: 3657 | L18: 4017 | M18: 3985 | N18: 4728
B19: Total Liabilities | C19: 8914 | D19: 10559 | E19: 12405 | F19: 13763 | G19: 16249 | H19: 16138 | I19: 20355 | J19: 22958 | K19: 25779 | L19: 29901 | M19: 30355 | N19: 34519
B21: Fixed Assets -
B22: Land | C22: 251 | D22: 429 | E22: 408 | F22: 586 | G22: 605 | H22: 640 | I22: 644 | J22: 644 | K22: 804 | L22: 1126 | M22: 1050
B23: Building | C23: 962 | D23: 923 | E23: 931 | F23: 957 | G23: 2402 | H23: 2257 | I23: 2249 | J23: 2325 | K23: 2883 | L23: 3390 | M23: 4136
B24: Plant Machinery | C24: 2132 | D24: 1793 | E24: 1980 | F24: 2157 | G24: 4006 | H24: 4208 | I24: 4340 | J24: 4531 | K24: 4825 | L24: 5422 | M24: 7576
B25: Equipments | C25: 171 | D25: 97 | E25: 119 | F25: 200 | G25: 221 | H25: 241 | I25: 243 | J25: 253 | K25: 270 | L25: 298 | M25: 325
B26: Furniture n fittings | C26: 83 | D26: 49 | E26: 59 | F26: 72 | G26: 88 | H26: 94 | I26: 99 | J26: 113 | K26: 146 | L26: 175 | M26: 203
B27: Vehicles | C27: 18 | D27: 11 | E27: 14 | F27: 27 | G27: 47 | H27: 43 | I27: 38 | J27: 32 | K27: 36 | L27: 40 | M27: 39
B28: Intangible Assets | C28: 351 | D28: 339 | E28: 276 | F28: 468 | G28: 512 | H28: 505 | I28: 476 | J28: 345 | K28: 422 | L28: 850 | M28: 827 | N28: 475
B29: Other fixed assets | C29: 145 | D29: 103 | E29: 128 | F29: 238 | G29: 261 | H29: 293 | I29: 302 | J29: 294 | K29: 289 | L29: 321 | M29: 328
B30: Gross Block | C30: 4112 | D30: 3744 | E30: 3914 | F30: 4705 | G30: 8141 | H30: 8282 | I30: 8392 | J30: 8538 | K30: 9676 | L30: 11622 | M30: 14484
B31: Accumulated Depreciation | C31: 1452 | D31: 327 | E31: 610 | F31: 973 | G31: 1644 | H31: 2010 | I31: 2533 | J31: 3019 | K31: 3905 | L31: 4475 | M31: 5264
B32: Net Block | C32: =SUM(C30-C31) -> 2660 | D32: =SUM(D30-D31) -> 3417 | E32: =SUM(E30-E31) -> 3304 | F32: =SUM(F30-F31) -> 3732 | G32: =SUM(G30-G31) -> 6497 | H32: =SUM(H30-H31) -> 6272 | I32: =SUM(I30-I31) -> 5859 | J32: =SUM(J30-J31) -> 5519 | ... M32: =SUM(M30-M31) -> 9220
B34: CWIP | C34: 196 | D34: 107 | E34: 258 | F34: 1405 | G34: 210 | H34: 140 | I34: 183 | J34: 426 | K34: 1020 | L34: 2698 | M34: 1254 | N34: 1849
B35: Investments | C35: 1588 | D35: 2712 | E35: 2652 | F35: 2141 | G35: 2569 | H35: 2019 | I35: 4737 | J35: 3248 | K35: 4262 | L35: 4588 | M35: 4725 | N35: 7062
B37: Other Assets -
B38: Inventories | C38: 2259 | D38: 1998 | E38: 2627 | F38: 2658 | G38: 3150 | H38: 3390 | I38: 3799 | J38: 6153 | K38: 6211 | L38: 5923 | M38: 6719 | N38: 5744
B39: Trade receivables | C39: 1182 | D39: 1187 | E39: 1447 | F39: 1731 | G39: 1907 | H39: 1795 | I39: 2602 | J39: 3871 | K39: 4637 | L39: 4889 | M39: 4314 | N39: 4462
B40: Cash Equivalents | C40: 204 | D40: 424 | E40: 801 | F40: 405 | G40: 445 | H40: 783 | I40: 611 | J40: 864 | K40: 844 | L40: 1084 | M40: 782 | N40: 1074
B41: Loans n Advances | C41: 8 | D41: 9 | E41: 14 | F41: 13 | G41: 16 | H41: 12 | I41: 11 | J41: 8 | K41: 12 | L41: 17 | M41: 22 | N41: 1545
B42: Other asset items | C42: 817 | D42: 705 | E42: 1303 | F42: 1678 | G42: 1456 | H42: 1727 | I42: 2555 | J42: 2869 | K42: 3024 | L42: 3555 | M42: 3319 | N42: 3159
B43: Total Assets | C43: 8914 | D43: 10559 | E43: 12405 | F43: 13763 | G43: 16249 | H43: 16138 | I43: 20355 | J43: 22958 | K43: 25779 | L43: 29901 | M43: 30355 | N43: 34519
B47: Cash from Operating Activity - | C47: 1188 | D47: 2243 | E47: 1527 | F47: 2113 | G47: 2470 | H47: 3038 | I47: 3683 | J47: 986 | K47: 4193 | L47: 6104 | M47: 4424 | N47: 7088
B48: Profit from operations | C48: 2271 | D48: 2848 | E48: 3056 | F48: 3274 | G48: 3861 | H48: 4380 | I48: 4970 | J48: 4957 | K48: 6460 | L48: 7929 | M48: 6390 | N48: 7186
B49: Receivables | C49: -155 | D49: -146 | E49: -475 | F49: -483 | G49: -205 | H49: 160 | I49: -849 | J49: -1326 | K49: -834 | L49: -362 | M49: 282 | N49: -274
B50: Inventory | C50: -144 | D50: 202 | E50: -629 | F50: -39 | G50: -492 | H50: -251 | I50: -409 | J50: -2354 | K50: -56 | L50: 315 | M50: -805 | N50: 976
...

Sheet ROIC
B3: Calculating ROIC of Asian Paints Using Intrinsic Value
B6: Calculation of ROIC | E6: 44256 | F6: 44621 | G6: 44986 | H6: 45352 | I6: 45717
A8: # | B8: Current Assets
B9: =Sheet1!B38 -> Inventories | E9: =Sheet1!I38 -> 3799 | F9: =Sheet1!J38 -> 6153 | G9: =Sheet1!K38 -> 6211 | H9: =Sheet1!L38 -> 5923 | I9: =Sheet1!M38 -> 6719
B10: =Sheet1!B39 -> Trade receivables | E10: =Sheet1!I39 -> 2602 | F10: =Sheet1!J39 -> 3871 | G10: =Sheet1!K39 -> 4637 | H10: =Sheet1!L39 -> 4889 | I10: =Sheet1!M39 -> 4314
B11: =Sheet1!B41 -> Loans n Advances | E11: =Sheet1!I41 -> 11 | F11: =Sheet1!J41 -> 8 | G11: =Sheet1!K41 -> 12 | H11: =Sheet1!L41 -> 17 | I11: =Sheet1!M41 -> 22
B12: =Sheet1!B42 -> Other asset items | E12: =Sheet1!I42 -> 2555 | F12: =Sheet1!J42 -> 2869 | G12: =Sheet1!K42 -> 3024 | H12: =Sheet1!L42 -> 3555 | I12: =Sheet1!M42 -> 3319
A13: # | B13: Total Current Assets | E13: =SUM(E9:E12) -> 8967 | F13: =SUM(F9:F12) -> 12901 | G13: =SUM(G9:G12) -> 13884 | H13: =SUM(H9:H12) -> 14384 | I13: =SUM(I9:I12) -> 14374
B15: Current Liabilities
B16: =Sheet1!B16 -> Trade Payables | E16: =Sheet1!I16 -> 3379 | F16: =Sheet1!J16 -> 4164 | G16: =Sheet1!K16 -> 3635 | H16: =Sheet1!L16 -> 3831 | I16: =Sheet1!M16 -> 3848
B17: =Sheet1!B17 -> Advance from Customers | E17: =Sheet1!I17 -> 41 | F17: =Sheet1!J17 -> 76 | G17: =Sheet1!K17 -> 108 | H17: =Sheet1!L17 -> 154 | I17: =Sheet1!M17 -> 173
B18: =Sheet1!B18 -> Other liability items | E18: =Sheet1!I18 -> 2613 | F18: =Sheet1!J18 -> 2932 | G18: =Sheet1!K18 -> 3657 | H18: =Sheet1!L18 -> 4017 | I18: =Sheet1!M18 -> 3985
A19: # | B19: Total Current Liabilities | E19: =SUM(E16:E18) -> 6033 | F19: =SUM(F16:F18) -> 7172 | G19: =SUM(G16:G18) -> 7400 | H19: =SUM(H16:H18) -> 8002 | I19: =SUM(I16:I18) -> 8006
A22: # | B22: Net Working Capital | E22: =E13-E19 -> 2934 | F22: =F13-F19 -> 5729 | G22: =G13-G19 -> 6484 | H22: =H13-H19 -> 6382 | I22: =I13-I19 -> 6368
A24: # | B24: Non Current Assets
B25: =Sheet1!B22 -> Land | E25: =Sheet1!I22 -> 644 | F25: =Sheet1!J22 -> 644 | G25: =Sheet1!K22 -> 804 | H25: =Sheet1!L22 -> 1126 | I25: =Sheet1!M22 -> 1050
B26: =Sheet1!B23 -> Building | E26: =Sheet1!I23 -> 2249 | F26: =Sheet1!J23 -> 2325 | G26: =Sheet1!K23 -> 2883 | H26: =Sheet1!L23 -> 3390 | I26: =Sheet1!M23 -> 4136
B27: =Sheet1!B24 -> Plant Machinery | E27: =Sheet1!I24 -> 4340 | F27: =Sheet1!J24 -> 4531 | G27: =Sheet1!K24 -> 4825 | H27: =Sheet1!L24 -> 5422 | I27: =Sheet1!M24 -> 7576
B28: =Sheet1!B25 -> Equipments | E28: =Sheet1!I25 -> 243 | F28: =Sheet1!J25 -> 253 | G28: =Sheet1!K25 -> 270 | H28: =Sheet1!L25 -> 298 | I28: =Sheet1!M25 -> 325
B29: =Sheet1!B26 -> Furniture n fittings | E29: =Sheet1!I26 -> 99 | F29: =Sheet1!J26 -> 113 | G29: =Sheet1!K26 -> 146 | H29: =Sheet1!L26 -> 175 | I29: =Sheet1!M26 -> 203
B30: =Sheet1!B27 -> Vehicles | E30: =Sheet1!I27 -> 38 | F30: =Sheet1!J27 -> 32 | G30: =Sheet1!K27 -> 36 | H30: =Sheet1!L27 -> 40 | I30: =Sheet1!M27 -> 39
B31: =Sheet1!B28 -> Intangible Assets | E31: =Sheet1!I28 -> 476 | F31: =Sheet1!J28 -> 345 | G31: =Sheet1!K28 -> 422 | H31: =Sheet1!L28 -> 850 | I31: =Sheet1!M28 -> 827
B32: =Sheet1!B29 -> Other fixed assets | E32: =Sheet1!I29 -> 302 | F32: =Sheet1!J29 -> 294 | G32: =Sheet1!K29 -> 289 | H32: =Sheet1!L29 -> 321 | I32: =Sheet1!M29 -> 328
A33: # | B33: Gross Block | E33: =SUM(E25:E32) -> 8391 | F33: =SUM(F25:F32) -> 8537 | G33: =SUM(G25:G32) -> 9675 | H33: =SUM(H25:H32) -> 11622 | I33: =SUM(I25:I32) -> 14484
B34: Accumulated Depreciation | E34: =-Sheet1!I31 -> -2533 | F34: =-Sheet1!J31 -> -3019 | G34: =-Sheet1!K31 -> -3905 | H34: =-Sheet1!L31 -> -4475 | I34: =-Sheet1!M31 -> -5264
A35: # | B35: Net Non Current Assets | E35: =E33+E34 -> 5858 | F35: =F33+F34 -> 5518 | G35: =G33+G34 -> 5770 | H35: =H33+H34 -> 7147 | I35: =I33+I34 -> 9220
B37: Invested Capital | E37: =SUM(E35+E22) -> 8792 | F37: =SUM(F35+F22) -> 11247 | G37: =SUM(G35+G22) -> 12254 | H37: =SUM(H35+H22) -> 13529 | I37: =SUM(I35+I22) -> 15588
B38: EBIT | E38: ='Raw Data'!I10+'Raw Data'!I8 -> 4396 | F38: ='Raw Data'!J10+'Raw Data'!J8 -> 4283 | G38: ='Raw Data'!K10+'Raw Data'!K8 -> 5833 | H38: ='Raw Data'!L10+'Raw Data'!L8 -> 7553 | I38: ='Raw Data'!M10+'Raw Data'!M8 -> 5330
A40: # | B40: ROIC | E40: =E38/E37 -> 0.5 | F40: =F38/F37 -> 0.38081266 | G40: =G38/G37 -> 0.47600783 | H40: =H38/H37 -> 0.55828221 | I40: =I38/I37 -> 0.34192969
B44: Calculation of Reinvestment Rate | E44: 44256 | F44: 44621 | G44: 44986 | H44: 45352 | I44: 45717
A46: # | B46: Net Capex | E46: =-SUM(Sheet1!I56:I57) -> 261 | F46: =-SUM(Sheet1!J56:J57) -> 511 | G46: =-SUM(Sheet1!K56:K57) -> 1420 | H46: =-SUM(Sheet1!L56:L57) -> 2491 | I46: =-SUM(Sheet1!M56:M57) -> 1820
B47: Change in Working Capital | F47: =F22-E22 -> 2795 | G47: =G22-F22 -> 755 | H47: =H22-G22 -> -102 | I47: =I22-H22 -> -14
B49: EBIT | E49: =E38 -> 4396 | F49: =F38 -> 4283 | G49: =G38 -> 5833 | H49: =H38 -> 7553 | I49: =I38 -> 5330
B50: Tax | E50: 0.25 | F50: 0.25 | G50: 0.25 | H50: 0.25 | I50: 0.25
A51: # | B51: EBIT(1-T) | E51: =E49*(1-E50) -> 3297 | F51: =F49*(1-F50) -> 3212.25 | G51: =G49*(1-G50) -> 4374.75 | H51: =H49*(1-H50) -> 5664.75 | I51: =I49*(1-I50) -> 3997.5
B53: Reinvestment | F53: =SUM(F46:F47) -> 3306 | G53: =SUM(G46:G47) -> 2175 | H53: =SUM(H46:H47) -> 2389 | I53: =SUM(I46:I47) -> 1806
A55: # | B55: Reinvestment Rate | F55: =F53/F51 -> 1.0291852 | G55: =G53/G51 -> 0.49717127 | H55: =H53/H51 -> 0.42173088 | I55: =I53/I51 -> 0.45178236
H57: 4 Year Average | I57: =AVERAGE(F55:I55) -> 0.59996742
H58: 4 Year Mean | I58: =MEDIAN(F55:I55) -> 0.47447682
B61: Calculation of Growth Rate | E61: 44256 | F61: 44621 | G61: 44986 | H61: 45352 | I61: 45717
...

Sheet Raw Data
B2: Particular | C2: 42064 | D2: 42430 | E2: 42795 | F2: 43160 | G2: 43525 | H2: 43891 | I2: 44256 | J2: 44621 | K2: 44986 | L2: 45352 | M2: 45717 | N2: 46082
B3: Sales | C3: 13615 | D3: 14271 | E3: 15062 | F3: 16825 | G3: 19240 | H3: 20211 | I3: 21713 | J3: 29101 | K3: 34489 | L3: 35495 | M3: 33906 | N3: 35584
B4: Expenses | C4: 11372 | D4: 11546 | E4: 12068 | F4: 13621 | G4: 15475 | H4: 16049 | I4: 16857 | J4: 24298 | K4: 28229 | L4: 27910 | M4: 27899 | N4: 28884
B5: Operating Profit | C5: 2243 | D5: 2725 | E5: 2994 | F5: 3204 | G5: 3765 | H5: 4162 | I5: 4856 | J5: 4804 | K5: 6260 | L5: 7585 | M5: 6006 | N5: 6700
B6: OPM % | C6: 0.16 | D6: 0.19 | E6: 0.2 | F6: 0.19 | G6: 0.2 | H6: 0.21 | I6: 0.22 | J6: 0.17 | K6: 0.18 | L6: 0.21 | M6: 0.18 | N6: 0.19
B7: Other Income | C7: 142 | D7: 213 | E7: 338 | F7: 336 | G7: 274 | H7: 350 | I7: 332 | J7: 296 | K7: 431 | L7: 821 | M7: 350 | N7: 728
B8: Interest | C8: 42 | D8: 49 | E8: 37 | F8: 41 | G8: 110 | H8: 102 | I8: 92 | J8: 95 | K8: 144 | L8: 205 | M8: 227 | N8: 195
B9: Depreciation | C9: 266 | D9: 276 | E9: 335 | F9: 360 | G9: 622 | H9: 780 | I9: 791 | J9: 816 | K9: 858 | L9: 853 | M9: 1026 | N9: 1229
B10: Profit before tax | C10: 2077 | D10: 2614 | E10: 2960 | F10: 3138 | G10: 3306 | H10: 3629 | I10: 4304 | J10: 4188 | K10: 5689 | L10: 7348 | M10: 5103 | N10: 6003
B11: Tax % | C11: 0.31 | D11: 0.32 | E11: 0.32 | F11: 0.33 | G11: 0.33 | H11: 0.24 | I11: 0.26 | J11: 0.26 | K11: 0.26 | L11: 0.24 | M11: 0.27 | N11: 0.27
B12: Net Profit | C12: 1427 | D12: 1803 | E12: 2016 | F12: 2098 | G12: 2208 | H12: 2774 | I12: 3207 | J12: 3085 | K12: 4195 | L12: 5558 | M12: 3710 | N12: 4395
B13: EPS in Rs | C13: 14.54 | D13: 18.19 | E13: 20.22 | F13: 21.26 | G13: 22.48 | H13: 28.2 | I13: 32.73 | J13: 31.59 | K13: 42.81 | L13: 56.92 | M13: 38.23 | N13: 45.09
... B47: CFO/OP | C47: 0.81 | D47: 1.12 | E47: 0.82 | F47: 1 | G47: 0.92 | H47: 0.97 | I47: 0.98 | J47: 0.45 | K47: 0.91 | L47: 1.05 | M47: 0.97 | N47: 1.29

Sheet FCFF
B1: Calculation of Discounted Future Cashflow of Asian Paints
B4: Calculation of PV of FCFF | E4: =ROIC!I6 -> 45717 | F4: =E4+365 -> 46082 | G4: =F4+365 -> 46447 | H4: 46813 | I4: 47178 | J4: 47543
B6: EBIT | E6: ='Raw Data'!M10-'Raw Data'!M9 -> 4077 | F6: =E6*(1+$C$15) -> 4922.9775 | G6: =F6*(1+$C$15) -> 5944.4953 | H6: =G6*(1+$C$15) -> 7177.9781 | I6: =H6*(1+$C$15) -> 8667.4086 | J6: =I6*(1+$C$15) -> 10465.896
B7: Tax Rate | E7: 0.27 | F7: 0.27 | G7: 0.27 | H7: 0.27 | I7: 0.27 | J7: 0.27
B8: EBIT(1-T) | E8: =E6*(1-E7) -> 2976.21 | F8: =F6*(1-F7) -> 3593.7736 | G8: =G6*(1-G7) -> 4339.4816 | H8: =H6*(1-H7) -> 5239.924 | I8: =I6*(1-I7) -> 6327.2083 | J8: =J6*(1-J7) -> 7640.104
B9: Less: Reinvestment Rate | E9: =ROIC!$I$58 -> 0.47447682 | F9: =E9+($J$9-$E$9)/4 -> 0.47870761 | G9: =F9+($J$9-$E$9)/4 -> 0.48293841 | H9: =G9+($J$9-$E$9)/4 -> 0.4871692 | I9: =H9+($J$9-$E$9)/4 -> 0.4914 | J9: 0.4914
B10: FCFF | E10: =E8*(1-E9) -> 1564.0674 | F10: =F8*(1-F9) -> 1873.4068 | G10: =G8*(1-G9) -> 2243.7793 | H10: =H8*(1-H9) -> 2687.1944 | I10: =I8*(1-I9) -> 3218.0181 | J10: =J8*(1-J9) -> 3885.7569
B11: Mid Year Convention | F11: 0.5 | G11: =F11+1 -> 1.5 | H11: =G11+1 -> 2.5 | I11: =H11+1 -> 3.5 | J11: =I11+1 -> 4.5
B12: Discounting Factor | F12: =1/(1+$C$17)^F11 -> 0.91271882 | G12: =1/(1+$C$17)^G11 -> 0.76034557 | H12: =1/(1+$C$17)^H11 -> 0.63341017 | I12: =1/(1+$C$17)^I11 -> 0.52766592 | J12: =1/(1+$C$17)^J11 -> 0.43957508
B13: PV of FCFF | F13: =F10*F12 -> 1709.8937 | G13: =G10*G12 -> 1706.0476 | H13: =H10*H12 -> 1702.0963 | I13: =I10*I12 -> 1698.0385 | J13: =J10*J12 -> 1708.0819
B15: Expected Growth | C15: 0.2075
B16: Terminal Growth | C16: 0.0538
B17: WACC | C17: 0.2004
B19: Calculation of Terminal Value
B21: FCFF(1+n) | C21: =J10*(1+C15) -> 4692.0514
B22: WACC | C22: =C17 -> 0.2004
B23: Terminal Growth | C23: =C16 -> 0.0538
B24: Terminal Value | C24: =C21/(C22-C23) -> 32005.808
B26: Calculation of Equity Value
B28: PV of FCFF | C28: =SUM(F13:J13) -> 8524.1579
B29: PV of Terminal Value | C29: =C24*J12 -> 14068.955
B30: Value of Enterprise | C30: =SUM(C28:C29) -> 22593.113
B32: Add: Cash | C32: =Sheet1!M40 -> 782
B33: Less: Debt | C33: =Sheet1!M10+Sheet1!M11 -> 864
B34: Value of Equity | C34: =C30+C32-C33 -> 22511.113
B35: No.of Shares | C35: 96
B36: Equity Value per share | C36: =C34/C35 -> 234.49076
B38: Share Price | C38: 2739
B39: Discount/Premium | C39: =C38/C36 -> 11.680631
